<sdf version='1.6'>
  <world name='default'>

    <light name='sun' type='directional'>
      <cast_shadows>1</cast_shadows>
      <pose frame=''>0 0 10 0 -0 0</pose>
      <diffuse>0.8 0.8 0.8 1</diffuse>
      <specular>0.2 0.2 0.2 1</specular>
      <attenuation>
        <range>1000</range>
        <constant>0.9</constant>
        <linear>0.01</linear>
        <quadratic>0.001</quadratic>
      </attenuation>
      <direction>-0.5 0.1 -0.9</direction>
    </light>

    <gravity>0 0 -9.8</gravity>

    <magnetic_field>6e-06 2.3e-05 -4.2e-05</magnetic_field>

    <atmosphere type='adiabatic'/>

    <physics name='default_physics' default='0' type='ode'>
      <max_step_size>0.001</max_step_size>
      <real_time_factor>1</real_time_factor>
      <real_time_update_rate>1000</real_time_update_rate>
    </physics>

    <scene>
      <ambient>0.4 0.4 0.4 1</ambient>
      <background>0.7 0.7 0.7 1</background>
      <shadows>1</shadows>
    </scene>

    <audio>
      <device>default</device>
    </audio>

    <wind/>

    <spherical_coordinates>
      <surface_model>EARTH_WGS84</surface_model>
      <latitude_deg>0</latitude_deg>
      <longitude_deg>0</longitude_deg>
      <elevation>0</elevation>
      <heading_deg>0</heading_deg>
    </spherical_coordinates>

    <model name='niryo_robot'>
      <link name='base_link'>
        <pose frame=''>0 0 0 0 -0 0</pose>
        <inertial>
          <pose frame=''>-0.002408 -0.005918 0.051577 0 -0 0</pose>
          <mass>0.999243</mass>
          <inertia>
            <ixx>0.002</ixx>
            <ixy>0</ixy>
            <ixz>0</ixz>
            <iyy>0.002</iyy>
            <iyz>0</iyz>
            <izz>0.004</izz>
          </inertia>
        </inertial>
        <collision name='base_link_collision'>
          <pose frame=''>0 0 0 0 -0 0</pose>
          <geometry>
            <mesh>
              <scale>1 1 1</scale>
              <uri>/STL/BASE_V1.stl</uri>
            </mesh>
          </geometry>
          <max_contacts>10</max_contacts>
          <surface>
            <contact>
              <ode/>
            </contact>
            <bounce/>
            <friction>
              <torsional>
                <ode/>
              </torsional>
              <ode/>
            </friction>
          </surface>
        </collision>
        <visual name='base_link_visual'>
          <pose frame=''>0 0 0 0 -0 0</pose>
          <geometry>
            <mesh>
              <scale>1 1 1</scale>
              <uri>collada/base_link.dae</uri>
            </mesh>
          </geometry>
        </visual>
        <self_collide>0</self_collide>
        <enable_wind>0</enable_wind>
        <kinematic>0</kinematic>
      </link>
      <joint name='joint_world' type='fixed'>
        <child>base_link</child>
        <parent>world</parent>
      </joint>
      <link name='shoulder_link'>
        <pose frame=''>0 0 0.1065 0 -0 0</pose>
        <inertial>
          <pose frame=''>-0.030731 0.005811 0.030228 0 -0 0</pose>
          <mass>0.474559</mass>
          <inertia>
            <ixx>0.0015</ixx>
            <ixy>0</ixy>
            <ixz>0</ixz>
            <iyy>0.0015</iyy>
            <iyz>0</iyz>
            <izz>0.0015</izz>
          </inertia>
        </inertial>
        <collision name='shoulder_link_collision'>
          <pose frame=''>0 0 0 0 -0 0</pose>
          <geometry>
            <mesh>
              <scale>1 1 1</scale>
              <uri>/stl/shoulder_link.stl</uri>
            </mesh>
          </geometry>
          <max_contacts>10</max_contacts>
          <surface>
            <contact>
              <ode/>
            </contact>
            <bounce/>
            <friction>
              <torsional>
                <ode/>
              </torsional>
              <ode/>
            </friction>
          </surface>
        </collision>
        <visual name='shoulder_link_visual'>
          <pose frame=''>0 0 0 0 -0 -1.57</pose>
          <geometry>
            <mesh>
              <scale>1 1 1</scale>
              <uri>collada/shoulder_link.dae</uri>
            </mesh>
          </geometry>
        </visual>
        <self_collide>0</self_collide>
        <enable_wind>0</enable_wind>
        <kinematic>0</kinematic>
      </link>
      <joint name='joint_1' type='revolute'>
        <child>shoulder_link</child>
        <parent>base_link</parent>
        <axis>
          <xyz>0 0 1</xyz>
          <limit>
            <lower>-2.96706</lower>
            <upper>2.96706</upper>
            <effort>10</effort>
            <velocity>2.2</velocity>
          </limit>
          <dynamics>
            <spring_reference>0</spring_reference>
            <spring_stiffness>0</spring_stiffness>
          </dynamics>
          <use_parent_model_frame>1</use_parent_model_frame>
        </axis>
      </joint>

      <link name='arm_link'>
        <pose frame=''>0 0 0.1715 -1.57079 -1.57079 3.14159</pose>
        <inertial>
          <pose frame=''>0.116485 -0.001412 -0.003381 0 -0 0</pose>
          <mass>0.513332</mass>
          <inertia>
            <ixx>0.0015</ixx>
            <ixy>0</ixy>
            <ixz>0</ixz>
            <iyy>0.0015</iyy>
            <iyz>0</iyz>
            <izz>0.0015</izz>
          </inertia>
        </inertial>

        <collision name='arm_link_collision'>
          <pose frame=''>0 0 0 0 -0 0</pose>
          <geometry>
            <mesh>
              <scale>1 1 1</scale>
              <uri>/stl2/arm_link.stl</uri>
            </mesh>
          </geometry>
          <max_contacts>10</max_contacts>
          <surface>
            <contact>
              <ode/>
            </contact>
            <bounce/>
            <friction>
              <torsional>
                <ode/>
              </torsional>
              <ode/>
            </friction>
          </surface>
        </collision>

        <visual name='arm_link_visual'>
          <pose frame=''>0 0 0 0 3.14 -1.57</pose>
          <geometry>
            <mesh>
              <scale>1 1 1</scale>
              <uri>collada/arm_link.dae</uri>
            </mesh>
          </geometry>
        </visual>

        <self_collide>0</self_collide>
        <enable_wind>0</enable_wind>
        <kinematic>0</kinematic>
      </link>

      <joint name='joint_2' type='revolute'>
        <child>arm_link</child>
        <parent>shoulder_link</parent>
        <axis>
          <xyz>0 -1 -0</xyz>
          <limit>
            <lower>-1.91009</lower>
            <upper>0.610167</upper>
            <effort>10</effort>
            <velocity>2.2</velocity>
          </limit>
          <dynamics>
            <spring_reference>0</spring_reference>
            <spring_stiffness>0</spring_stiffness>
          </dynamics>
          <use_parent_model_frame>1</use_parent_model_frame>
        </axis>
      </joint>
      <link name='elbow_link'>
        <pose frame=''>0.012 0 0.3925 1.5708 -0 0</pose>
        <inertial>
          <pose frame=''>0.008405 0.023513 0.001398 0 -0 0</pose>
          <mass>0.201039</mass>
          <inertia>
            <ixx>0.0015</ixx>
            <ixy>0</ixy>
            <ixz>0</ixz>
            <iyy>0.0015</iyy>
            <iyz>0</iyz>
            <izz>0.0015</izz>
          </inertia>
        </inertial>
        <collision name='elbow_link_collision'>
          <pose frame=''>0 0 0 0 -0 0</pose>
          <geometry>
            <mesh>
              <scale>1 1 1</scale>
              <uri>/stl/elbow_link.stl</uri>
            </mesh>
          </geometry>
          <max_contacts>10</max_contacts>
          <surface>
            <contact>
              <ode/>
            </contact>
            <bounce/>
            <friction>
              <torsional>
                <ode/>
              </torsional>
              <ode/>
            </friction>
          </surface>
        </collision>
        <visual name='elbow_link_visual'>
          <pose frame=''>0 0 0 0 -0 0</pose>
          <geometry>
            <mesh>
              <scale>1 1 1</scale>
              <uri>collada/elbow_link.dae</uri>
            </mesh>
          </geometry>
        </visual>
        <self_collide>0</self_collide>
        <enable_wind>0</enable_wind>
        <kinematic>0</kinematic>
      </link>
      <joint name='joint_3' type='revolute'>
        <child>elbow_link</child>
        <parent>arm_link</parent>
        <axis>
          <xyz>0 -1 -0</xyz>
          <limit>
            <lower>-1.34006</lower>
            <upper>1.5701</upper>
            <effort>7</effort>
            <velocity>2</velocity>
          </limit>
          <dynamics>
            <spring_reference>0</spring_reference>
            <spring_stiffness>0</spring_stiffness>
          </dynamics>
          <use_parent_model_frame>1</use_parent_model_frame>
        </axis>
      </joint>

      <link name='forearm_link'>
        <pose frame=''>0.059 0 0.425 1.5708 -0 1.5708</pose>
        <inertial>
          <pose frame=''>-0.008113 -0.000136 0.107402 0 -0 0</pose>
          <mass>0.407088</mass>
          <inertia>
            <ixx>0.003</ixx>
            <ixy>0</ixy>
            <ixz>0</ixz>
            <iyy>0.003</iyy>
            <iyz>0</iyz>
            <izz>0.003</izz>
          </inertia>
        </inertial>
        <collision name='forearm_link_collision'>
          <pose frame=''>0 0 0 0 -0 0</pose>
          <geometry>
            <mesh>
              <scale>1 1 1</scale>
              <uri>/stl/forearm_link.stl</uri>
            </mesh>
          </geometry>
          <max_contacts>10</max_contacts>
          <surface>
            <contact>
              <ode/>
            </contact>
            <bounce/>
            <friction>
              <torsional>
                <ode/>
              </torsional>
              <ode/>
            </friction>
          </surface>
        </collision>

        <collision name='forearm_link_fixed_joint_lump__joint5_motor_collision_1'>
          <pose frame=''>-0.045 0 0.1765 0 -0 0</pose>
          <geometry>
            <box>
              <size>0.0435 0.0285 0.0465</size>
            </box>
          </geometry>
          <max_contacts>10</max_contacts>
          <surface>
            <contact>
              <ode/>
            </contact>
            <bounce/>
            <friction>
              <torsional>
                <ode/>
              </torsional>
              <ode/>
            </friction>
          </surface>
        </collision>

        <visual name='forearm_link_visual'>
          <pose frame=''>0 0 0 0 -0 0</pose>
          <geometry>
            <mesh>
              <scale>1 1 1</scale>
              <uri>collada/forearm_link.dae</uri>
            </mesh>
          </geometry>
        </visual>
        <self_collide>0</self_collide>
        <enable_wind>0</enable_wind>
        <kinematic>0</kinematic>
      </link>

      <joint name='joint_4' type='revolute'>
        <child>forearm_link</child>
        <parent>elbow_link</parent>
        <axis>
          <xyz>1 0 0</xyz>
          <limit>
            <lower>-2.09003</lower>
            <upper>2.09003</upper>
            <effort>7</effort>
            <velocity>2</velocity>
          </limit>
          <dynamics>
            <spring_reference>0</spring_reference>
            <spring_stiffness>0</spring_stiffness>
          </dynamics>
          <use_parent_model_frame>1</use_parent_model_frame>
        </axis>
      </joint>
      <link name='wrist_link'>
        <pose frame=''>0.247 0 0.425 1.5708 -0 0</pose>
        <inertial>
          <pose frame=''>-0.019323 -0.00157 0.000276 0 -0 0</pose>
          <mass>0.0403595</mass>
          <inertia>
            <ixx>0.0015</ixx>
            <ixy>0</ixy>
            <ixz>0</ixz>
            <iyy>0.0015</iyy>
            <iyz>0</iyz>
            <izz>0.0015</izz>
          </inertia>
        </inertial>
        <collision name='wrist_link_collision'>
          <pose frame=''>0 0 0 0 -0 0</pose>
          <geometry>
            <mesh>
              <scale>1 1 1</scale>
              <uri>/stl/wrist_link.stl</uri>
            </mesh>
          </geometry>
          <max_contacts>10</max_contacts>
          <surface>
            <contact>
              <ode/>
            </contact>
            <bounce/>
            <friction>
              <torsional>
                <ode/>
              </torsional>
              <ode/>
            </friction>
          </surface>
        </collision>
        <visual name='wrist_link_visual'>
          <pose frame=''>0 0 0 0 -0 0</pose>
          <geometry>
            <mesh>
              <scale>1 1 1</scale>
              <uri>collada/wrist_link.dae</uri>
            </mesh>
          </geometry>
        </visual>
        <visual name='wrist_link_fixed_joint_lump__camera_link_visual_1'>
          <pose frame=''>0 0.0385 0 -1.5708 0 0</pose>
          <geometry>
            <box>
              <size>0.01 0.037 0.037</size>
            </box>
          </geometry>
          <material>
            <script>
              <name>Gazebo/DarkGrey</name>
              <uri>file://media/materials/scripts/gazebo.material</uri>
            </script>
          </material>
        </visual>
        <gravity>1</gravity>
        <velocity_decay/>
        <sensor name='camera_gazebo' type='camera'>
          <update_rate>15</update_rate>
          <camera name='head'>
            <horizontal_fov>1.21</horizontal_fov>
            <image>
              <width>640</width>
              <height>480</height>
              <format>R8G8B8</format>
            </image>
            <clip>
              <near>0.03</near>
              <far>2</far>
            </clip>
            <distortion>
              <k1>-0.41464</k1>
              <k2>0.240738</k2>
              <p1>-0</p1>
              <p2>-0</p2>
              <k3>-0.104004</k3>
              <center>0.5 0.5</center>
            </distortion>
          </camera>
          <plugin name='camera_controller' filename='libgazebo_ros_camera.so'>
            <alwaysOn>1</alwaysOn>
            <updateRate>0.0</updateRate>
            <cameraName>gazebo_camera</cameraName>
            <imageTopicName>image_raw</imageTopicName>
            <cameraInfoTopicName>camera_info</cameraInfoTopicName>
            <frameName>camera_link</frameName>
            <robotNamespace>/</robotNamespace>
          </plugin>
          <pose frame=''>0 0.0385 0 -1.5708 0 0</pose>
        </sensor>
        <self_collide>0</self_collide>
        <enable_wind>0</enable_wind>
        <kinematic>0</kinematic>
      </link>
      <joint name='joint_5' type='revolute'>
        <child>wrist_link</child>
        <parent>forearm_link</parent>
        <axis>
          <xyz>0 -1 -0</xyz>
          <limit>
            <lower>-1.92004</lower>
            <upper>1.05016</upper>
            <effort>6</effort>
            <velocity>2</velocity>
          </limit>
          <dynamics>
            <spring_reference>0</spring_reference>
            <spring_stiffness>0</spring_stiffness>
          </dynamics>
          <use_parent_model_frame>1</use_parent_model_frame>
        </axis>
      </joint>
      <link name='hand_link'>
        <pose frame=''>0.2667 0 0.43425 1.5708 -0 1.5708</pose>
        <inertial>
          <pose frame=''>0.001497 0.000122 0.009475 0 -0 0</pose>
          <mass>0.015877</mass>
          <inertia>
            <ixx>0.00150111</ixx>
            <ixy>-4.80106e-08</ixy>
            <ixz>-2.33074e-07</ixz>
            <iyy>0.00150163</iyy>
            <iyz>-2.11326e-08</iyz>
            <izz>0.00150153</izz>
          </inertia>
        </inertial>
        <collision name='hand_link_collision'>
          <pose frame=''>0 0 0 0 -0 0</pose>
          <geometry>
            <mesh>
              <scale>1 1 1</scale>
              <uri>/stl/hand_link.stl</uri>
            </mesh>
          </geometry>
          <max_contacts>10</max_contacts>
          <surface>
            <contact>
              <ode/>
            </contact>
            <bounce/>
            <friction>
              <torsional>
                <ode/>
              </torsional>
              <ode/>
            </friction>
          </surface>
        </collision>
        
        <visual name='hand_link_visual'>
          <pose frame=''>0 0 0 0 -0 0</pose>
          <geometry>
            <mesh>
              <scale>1 1 1</scale>
              <uri>collada/hand_link.dae</uri>
            </mesh>
          </geometry>
        </visual>
       
        <gravity>1</gravity>
        <velocity_decay/>
        <self_collide>0</self_collide>
        <enable_wind>0</enable_wind>
        <kinematic>0</kinematic>
      </link>
      <joint name='joint_6' type='revolute'>
        <child>hand_link</child>
        <parent>wrist_link</parent>
        <axis>
          <xyz>1 0 -0</xyz>
          <limit>
            <lower>-2.53003</lower>
            <upper>2.53003</upper>
            <effort>5</effort>
            <velocity>2</velocity>
          </limit>
          <dynamics>
            <spring_reference>0</spring_reference>
            <spring_stiffness>0</spring_stiffness>
          </dynamics>
          <use_parent_model_frame>1</use_parent_model_frame>
        </axis>
      </joint>


      <plugin name='gazebo_ros_control' filename='libgazebo_ros_control.so'>
        <robotSimType>gazebo_ros_control/DefaultRobotHWSim</robotSimType>
        <robotNamespace>/</robotNamespace>
      </plugin>

      <static>0</static>

      <plugin name='passive_joint_state_publisher' filename='libgazebo_ros_joint_state_publisher.so'>
        <jointName>joint_1, joint_2, joint_3, joint_4, joint_5, joint_6</jointName>
        <updateRate>50.0</updateRate>
        <alwaysOn>1</alwaysOn>
        <robotNamespace>/</robotNamespace>
      </plugin>

      <pose frame=''>0 0 0 0 -0 0</pose>
    </model>

    <state world_name='default'>

      <sim_time>35 11000000</sim_time>
      <real_time>38 344984388</real_time>
      <wall_time>1705600157 723798495</wall_time>
      <iterations>35011</iterations>

      <model name='ground_plane'>
        <pose frame=''>0 0 0 0 -0 0</pose>
        <scale>1 1 1</scale>
        <link name='link'>
          <pose frame=''>0 0 0 0 -0 0</pose>
          <velocity>0 0 0 0 -0 0</velocity>
          <acceleration>0 0 0 0 -0 0</acceleration>
          <wrench>0 0 0 0 -0 0</wrench>
        </link>
      </model>

      <model name='niryo_robot'>
        <pose frame=''>0 0 0 0 -2e-06 0</pose>
        <scale>1 1 1</scale>

        <link name='arm_link'>
          <pose frame=''>5e-06 -0 0.171501 1.64217 -1.57079 -0.071379</pose>
          <velocity>2e-06 -1.8e-05 -3e-06 0.000227 0.003518 0.000131</velocity>
          <acceleration>0.080082 -0.121875 -0.003195 0.595134 0.506676 0.289151</acceleration>
          <wrench>0.041109 -0.062562 -0.00164 0 -0 0</wrench>
        </link>

        <link name='base_link'>
          <pose frame=''>0 0 0 0 -2e-06 0</pose>
          <velocity>-1e-06 5e-06 1.3e-05 0.000413 0.000354 3e-05</velocity>
          <acceleration>0.041148 -0.036705 0.026195 0.923555 0.845228 0.061113</acceleration>
          <wrench>0.041117 -0.036678 0.026175 0 -0 0</wrench>
        </link>

        <link name='elbow_link'>
          <pose frame=''>0.012009 -0 0.392501 1.5708 1.9e-05 -9e-06</pose>
          <velocity>0.000766 -5.3e-05 -4.3e-05 7.1e-05 0.005614 0.000204</velocity>
          <acceleration>0.109266 -0.15348 -0.006456 0.262842 0.15556 0.448896</acceleration>
          <wrench>0.021967 -0.030855 -0.001298 0 -0 0</wrench>
        </link>

        <link name='forearm_link'>
          <pose frame=''>0.05901 -1e-06 0.424999 1.57083 -5e-06 1.57079</pose>
          <velocity>0.000942 -3.5e-05 -0.0003 7.6e-05 0.005539 0.000287</velocity>
          <acceleration>0.102682 -0.04817 9.5e-05 0.196751 -0.005619 0.631968</acceleration>
          <wrench>0.041801 -0.019609 3.9e-05 0 -0 0</wrench>
        </link>

        <link name='hand_link'>
          <pose frame=''>0.266711 -3e-06 0.434243 1.57083 -6e-06 1.57079</pose>
          <velocity>0.000991 2.9e-05 -0.001452 6.2e-05 0.005742 0.000291</velocity>
          <acceleration>0.086925 0.030449 0.009987 0.152843 -0.059787 0.643287</acceleration>
          <wrench>0.00138 0.000483 0.000159 0 -0 0</wrench>
        </link>

        <link name='shoulder_link'>
          <pose frame=''>1e-06 -0 0.106501 0 1.4e-05 -1e-05</pose>
          <velocity>2.2e-05 -3.1e-05 -5e-06 0.000484 0.000419 1.8e-05</velocity>
          <acceleration>0.088521 -0.107574 0.030812 1.13713 1.0467 0.045144</acceleration>
          <wrench>0.042009 -0.05105 0.014622 0 -0 0</wrench>
        </link>

        <link name='wrist_link'>
          <pose frame=''>0.24701 -3e-06 0.424994 1.57081 2.6e-05 -9e-06</pose>
          <velocity>0.000941 2.1e-05 -0.001341 6.7e-05 0.005756 0.000291</velocity>
          <acceleration>0.094259 -0.004682 0.003581 0.17633 -0.02987 0.641404</acceleration>
          <wrench>0.003804 -0.000189 0.000145 0 -0 0</wrench>
        </link>
      </model>

      <light name='sun'>
        <pose frame=''>0 0 10 0 -0 0</pose>
      </light>

    </state>

    <gui fullscreen='0'>
      <camera name='user_camera'>
        <pose frame=''>1.48374 -1.40341 0.870123 0 0.275643 2.35619</pose>
        <view_controller>orbit</view_controller>
        <projection_type>perspective</projection_type>
      </camera>
    </gui>
  </world>

</sdf>
